<mujoco>
    <option gravity='0 0 0'/>
    
    <visual>
        <headlight diffuse='0.5 0.5 0.5'/>
    </visual>

    <worldbody>
        <geom type="plane" size="5 5 0.1" rgba="0 .9 0 1"/>
        <body pos='1 0 0.1' euler='0 90 0'>
            <joint type='hinge' pos='0 0 -1' axis='-1 0 0'/>
            <geom type="cylinder" size=".1 1" rgba="1 0 0 1"/>
            <body pos='0 0 2' euler='0 0 0'>
                <joint type='hinge' pos='0 0 -1' axis='-1 0 0'/>
                <geom type="cylinder" size=".1 1" rgba="0 1 1 1"/>
                <site name = 'tip' type="sphere" size="0.2" rgba="0.5 0.5 0.5 1" pos="0 0 1"/>
            </body>
        </body>
    </worldbody>
    <sensor>
        <framepos name='tip_sense' objname="tip" objtype="site"/>
    </sensor>

</mujoco>